2020-03-26 19:38:57,624:INFO:discord.client: logging in using static token
2020-03-26 19:38:59,054:INFO:discord.gateway: Created websocket connected to wss://gateway.discord.gg?encoding=json&v=6&compress=zlib-stream
2020-03-26 19:38:59,059:INFO:discord.gateway: Shard ID None has sent the IDENTIFY payload.
2020-03-26 19:38:59,464:INFO:discord.gateway: Shard ID None has connected to Gateway: ["gateway-prd-main-dtzt",{"micros":90512,"calls":["discord-sessions-prd-1-10",{"micros":85865,"calls":["start_session",{"micros":83343,"calls":["api-prd-main-m8m1",{"micros":78314,"calls":["get_user",{"micros":12806},"add_authorized_ip",{"micros":1436},"get_guilds",{"micros":17513},"coros_wait",{"micros":2}]}]},"guilds_connect",{"micros":2,"calls":[]},"presence_connect",{"micros":1797,"calls":[]}]}]}] (Session ID: e8f2154af00ee118b27cb9d022623827).
2020-03-26 19:46:26,632:INFO:discord.gateway: Websocket closed with 1006 (), attempting a reconnect.
2020-03-26 19:46:26,633:INFO:discord.client: Got a request to RESUME the websocket.
2020-03-26 19:46:32,831:WARNING:discord.gateway: Shard ID None has stopped responding to the gateway. Closing and restarting.
2020-03-26 19:46:41,662:ERROR:discord.client: Attempting a reconnect in 0.70s
Traceback (most recent call last):
  File "/home/anshuln/.local/lib/python3.6/site-packages/aiohttp/connector.py", line 967, in _create_direct_connection
    traces=traces), loop=self._loop)
  File "/home/anshuln/.local/lib/python3.6/site-packages/aiohttp/connector.py", line 830, in _resolve_host
    self._resolver.resolve(host, port, family=self._family)
  File "/home/anshuln/.local/lib/python3.6/site-packages/aiohttp/resolver.py", line 30, in resolve
    host, port, type=socket.SOCK_STREAM, family=family)
  File "/usr/lib/python3.6/concurrent/futures/thread.py", line 56, in run
    result = self.fn(*self.args, **self.kwargs)
  File "/usr/lib/python3.6/socket.py", line 745, in getaddrinfo
    for res in _socket.getaddrinfo(host, port, family, type, proto, flags):
socket.gaierror: [Errno -2] Name or service not known

The above exception was the direct cause of the following exception:

Traceback (most recent call last):
  File "/home/anshuln/.local/lib/python3.6/site-packages/discord/client.py", line 499, in connect
    await self._connect()
  File "/home/anshuln/.local/lib/python3.6/site-packages/discord/client.py", line 469, in _connect
    self.ws = await asyncio.wait_for(coro, timeout=180.0)
  File "/usr/lib/python3.6/asyncio/tasks.py", line 358, in wait_for
    return fut.result()
  File "/home/anshuln/.local/lib/python3.6/site-packages/discord/gateway.py", line 224, in from_client
    gateway = await client.http.get_gateway()
  File "/home/anshuln/.local/lib/python3.6/site-packages/discord/http.py", line 827, in get_gateway
    data = await self.request(Route('GET', '/gateway'))
  File "/home/anshuln/.local/lib/python3.6/site-packages/discord/http.py", line 165, in request
    async with self.__session.request(method, url, **kwargs) as r:
  File "/home/anshuln/.local/lib/python3.6/site-packages/aiohttp/client.py", line 1012, in __aenter__
    self._resp = await self._coro
  File "/home/anshuln/.local/lib/python3.6/site-packages/aiohttp/client.py", line 483, in _request
    timeout=real_timeout
  File "/home/anshuln/.local/lib/python3.6/site-packages/aiohttp/connector.py", line 523, in connect
    proto = await self._create_connection(req, traces, timeout)
  File "/home/anshuln/.local/lib/python3.6/site-packages/aiohttp/connector.py", line 859, in _create_connection
    req, traces, timeout)
  File "/home/anshuln/.local/lib/python3.6/site-packages/aiohttp/connector.py", line 971, in _create_direct_connection
    raise ClientConnectorError(req.connection_key, exc) from exc
aiohttp.client_exceptions.ClientConnectorError: Cannot connect to host discordapp.com:443 ssl:default [Name or service not known]
2020-03-26 19:46:57,491:ERROR:discord.client: Attempting a reconnect in 1.53s
Traceback (most recent call last):
  File "/home/anshuln/.local/lib/python3.6/site-packages/aiohttp/connector.py", line 967, in _create_direct_connection
    traces=traces), loop=self._loop)
  File "/home/anshuln/.local/lib/python3.6/site-packages/aiohttp/connector.py", line 830, in _resolve_host
    self._resolver.resolve(host, port, family=self._family)
  File "/home/anshuln/.local/lib/python3.6/site-packages/aiohttp/resolver.py", line 30, in resolve
    host, port, type=socket.SOCK_STREAM, family=family)
  File "/usr/lib/python3.6/concurrent/futures/thread.py", line 56, in run
    result = self.fn(*self.args, **self.kwargs)
  File "/usr/lib/python3.6/socket.py", line 745, in getaddrinfo
    for res in _socket.getaddrinfo(host, port, family, type, proto, flags):
socket.gaierror: [Errno -2] Name or service not known

The above exception was the direct cause of the following exception:

Traceback (most recent call last):
  File "/home/anshuln/.local/lib/python3.6/site-packages/discord/client.py", line 499, in connect
    await self._connect()
  File "/home/anshuln/.local/lib/python3.6/site-packages/discord/client.py", line 460, in _connect
    self.ws = await asyncio.wait_for(coro, timeout=180.0)
  File "/usr/lib/python3.6/asyncio/tasks.py", line 358, in wait_for
    return fut.result()
  File "/home/anshuln/.local/lib/python3.6/site-packages/discord/gateway.py", line 224, in from_client
    gateway = await client.http.get_gateway()
  File "/home/anshuln/.local/lib/python3.6/site-packages/discord/http.py", line 827, in get_gateway
    data = await self.request(Route('GET', '/gateway'))
  File "/home/anshuln/.local/lib/python3.6/site-packages/discord/http.py", line 165, in request
    async with self.__session.request(method, url, **kwargs) as r:
  File "/home/anshuln/.local/lib/python3.6/site-packages/aiohttp/client.py", line 1012, in __aenter__
    self._resp = await self._coro
  File "/home/anshuln/.local/lib/python3.6/site-packages/aiohttp/client.py", line 483, in _request
    timeout=real_timeout
  File "/home/anshuln/.local/lib/python3.6/site-packages/aiohttp/connector.py", line 523, in connect
    proto = await self._create_connection(req, traces, timeout)
  File "/home/anshuln/.local/lib/python3.6/site-packages/aiohttp/connector.py", line 859, in _create_connection
    req, traces, timeout)
  File "/home/anshuln/.local/lib/python3.6/site-packages/aiohttp/connector.py", line 971, in _create_direct_connection
    raise ClientConnectorError(req.connection_key, exc) from exc
aiohttp.client_exceptions.ClientConnectorError: Cannot connect to host discordapp.com:443 ssl:default [Name or service not known]
2020-03-26 19:47:14,054:ERROR:discord.client: Attempting a reconnect in 4.93s
Traceback (most recent call last):
  File "/home/anshuln/.local/lib/python3.6/site-packages/aiohttp/connector.py", line 967, in _create_direct_connection
    traces=traces), loop=self._loop)
  File "/home/anshuln/.local/lib/python3.6/site-packages/aiohttp/connector.py", line 830, in _resolve_host
    self._resolver.resolve(host, port, family=self._family)
  File "/home/anshuln/.local/lib/python3.6/site-packages/aiohttp/resolver.py", line 30, in resolve
    host, port, type=socket.SOCK_STREAM, family=family)
  File "/usr/lib/python3.6/concurrent/futures/thread.py", line 56, in run
    result = self.fn(*self.args, **self.kwargs)
  File "/usr/lib/python3.6/socket.py", line 745, in getaddrinfo
    for res in _socket.getaddrinfo(host, port, family, type, proto, flags):
socket.gaierror: [Errno -2] Name or service not known

The above exception was the direct cause of the following exception:

Traceback (most recent call last):
  File "/home/anshuln/.local/lib/python3.6/site-packages/discord/client.py", line 499, in connect
    await self._connect()
  File "/home/anshuln/.local/lib/python3.6/site-packages/discord/client.py", line 460, in _connect
    self.ws = await asyncio.wait_for(coro, timeout=180.0)
  File "/usr/lib/python3.6/asyncio/tasks.py", line 358, in wait_for
    return fut.result()
  File "/home/anshuln/.local/lib/python3.6/site-packages/discord/gateway.py", line 224, in from_client
    gateway = await client.http.get_gateway()
  File "/home/anshuln/.local/lib/python3.6/site-packages/discord/http.py", line 827, in get_gateway
    data = await self.request(Route('GET', '/gateway'))
  File "/home/anshuln/.local/lib/python3.6/site-packages/discord/http.py", line 165, in request
    async with self.__session.request(method, url, **kwargs) as r:
  File "/home/anshuln/.local/lib/python3.6/site-packages/aiohttp/client.py", line 1012, in __aenter__
    self._resp = await self._coro
  File "/home/anshuln/.local/lib/python3.6/site-packages/aiohttp/client.py", line 483, in _request
    timeout=real_timeout
  File "/home/anshuln/.local/lib/python3.6/site-packages/aiohttp/connector.py", line 523, in connect
    proto = await self._create_connection(req, traces, timeout)
  File "/home/anshuln/.local/lib/python3.6/site-packages/aiohttp/connector.py", line 859, in _create_connection
    req, traces, timeout)
  File "/home/anshuln/.local/lib/python3.6/site-packages/aiohttp/connector.py", line 971, in _create_direct_connection
    raise ClientConnectorError(req.connection_key, exc) from exc
aiohttp.client_exceptions.ClientConnectorError: Cannot connect to host discordapp.com:443 ssl:default [Name or service not known]
2020-03-26 19:47:34,011:ERROR:discord.client: Attempting a reconnect in 11.27s
Traceback (most recent call last):
  File "/home/anshuln/.local/lib/python3.6/site-packages/aiohttp/connector.py", line 967, in _create_direct_connection
    traces=traces), loop=self._loop)
  File "/home/anshuln/.local/lib/python3.6/site-packages/aiohttp/connector.py", line 830, in _resolve_host
    self._resolver.resolve(host, port, family=self._family)
  File "/home/anshuln/.local/lib/python3.6/site-packages/aiohttp/resolver.py", line 30, in resolve
    host, port, type=socket.SOCK_STREAM, family=family)
  File "/usr/lib/python3.6/concurrent/futures/thread.py", line 56, in run
    result = self.fn(*self.args, **self.kwargs)
  File "/usr/lib/python3.6/socket.py", line 745, in getaddrinfo
    for res in _socket.getaddrinfo(host, port, family, type, proto, flags):
socket.gaierror: [Errno -2] Name or service not known

The above exception was the direct cause of the following exception:

Traceback (most recent call last):
  File "/home/anshuln/.local/lib/python3.6/site-packages/discord/client.py", line 499, in connect
    await self._connect()
  File "/home/anshuln/.local/lib/python3.6/site-packages/discord/client.py", line 460, in _connect
    self.ws = await asyncio.wait_for(coro, timeout=180.0)
  File "/usr/lib/python3.6/asyncio/tasks.py", line 358, in wait_for
    return fut.result()
  File "/home/anshuln/.local/lib/python3.6/site-packages/discord/gateway.py", line 224, in from_client
    gateway = await client.http.get_gateway()
  File "/home/anshuln/.local/lib/python3.6/site-packages/discord/http.py", line 827, in get_gateway
    data = await self.request(Route('GET', '/gateway'))
  File "/home/anshuln/.local/lib/python3.6/site-packages/discord/http.py", line 165, in request
    async with self.__session.request(method, url, **kwargs) as r:
  File "/home/anshuln/.local/lib/python3.6/site-packages/aiohttp/client.py", line 1012, in __aenter__
    self._resp = await self._coro
  File "/home/anshuln/.local/lib/python3.6/site-packages/aiohttp/client.py", line 483, in _request
    timeout=real_timeout
  File "/home/anshuln/.local/lib/python3.6/site-packages/aiohttp/connector.py", line 523, in connect
    proto = await self._create_connection(req, traces, timeout)
  File "/home/anshuln/.local/lib/python3.6/site-packages/aiohttp/connector.py", line 859, in _create_connection
    req, traces, timeout)
  File "/home/anshuln/.local/lib/python3.6/site-packages/aiohttp/connector.py", line 971, in _create_direct_connection
    raise ClientConnectorError(req.connection_key, exc) from exc
aiohttp.client_exceptions.ClientConnectorError: Cannot connect to host discordapp.com:443 ssl:default [Name or service not known]
2020-03-26 19:48:00,306:ERROR:discord.client: Attempting a reconnect in 7.89s
Traceback (most recent call last):
  File "/home/anshuln/.local/lib/python3.6/site-packages/aiohttp/connector.py", line 967, in _create_direct_connection
    traces=traces), loop=self._loop)
  File "/home/anshuln/.local/lib/python3.6/site-packages/aiohttp/connector.py", line 830, in _resolve_host
    self._resolver.resolve(host, port, family=self._family)
  File "/home/anshuln/.local/lib/python3.6/site-packages/aiohttp/resolver.py", line 30, in resolve
    host, port, type=socket.SOCK_STREAM, family=family)
  File "/usr/lib/python3.6/concurrent/futures/thread.py", line 56, in run
    result = self.fn(*self.args, **self.kwargs)
  File "/usr/lib/python3.6/socket.py", line 745, in getaddrinfo
    for res in _socket.getaddrinfo(host, port, family, type, proto, flags):
socket.gaierror: [Errno -2] Name or service not known

The above exception was the direct cause of the following exception:

Traceback (most recent call last):
  File "/home/anshuln/.local/lib/python3.6/site-packages/discord/client.py", line 499, in connect
    await self._connect()
  File "/home/anshuln/.local/lib/python3.6/site-packages/discord/client.py", line 460, in _connect
    self.ws = await asyncio.wait_for(coro, timeout=180.0)
  File "/usr/lib/python3.6/asyncio/tasks.py", line 358, in wait_for
    return fut.result()
  File "/home/anshuln/.local/lib/python3.6/site-packages/discord/gateway.py", line 224, in from_client
    gateway = await client.http.get_gateway()
  File "/home/anshuln/.local/lib/python3.6/site-packages/discord/http.py", line 827, in get_gateway
    data = await self.request(Route('GET', '/gateway'))
  File "/home/anshuln/.local/lib/python3.6/site-packages/discord/http.py", line 165, in request
    async with self.__session.request(method, url, **kwargs) as r:
  File "/home/anshuln/.local/lib/python3.6/site-packages/aiohttp/client.py", line 1012, in __aenter__
    self._resp = await self._coro
  File "/home/anshuln/.local/lib/python3.6/site-packages/aiohttp/client.py", line 483, in _request
    timeout=real_timeout
  File "/home/anshuln/.local/lib/python3.6/site-packages/aiohttp/connector.py", line 523, in connect
    proto = await self._create_connection(req, traces, timeout)
  File "/home/anshuln/.local/lib/python3.6/site-packages/aiohttp/connector.py", line 859, in _create_connection
    req, traces, timeout)
  File "/home/anshuln/.local/lib/python3.6/site-packages/aiohttp/connector.py", line 971, in _create_direct_connection
    raise ClientConnectorError(req.connection_key, exc) from exc
aiohttp.client_exceptions.ClientConnectorError: Cannot connect to host discordapp.com:443 ssl:default [Name or service not known]
2020-03-26 19:48:23,221:ERROR:discord.client: Attempting a reconnect in 60.29s
Traceback (most recent call last):
  File "/home/anshuln/.local/lib/python3.6/site-packages/aiohttp/connector.py", line 967, in _create_direct_connection
    traces=traces), loop=self._loop)
  File "/home/anshuln/.local/lib/python3.6/site-packages/aiohttp/connector.py", line 830, in _resolve_host
    self._resolver.resolve(host, port, family=self._family)
  File "/home/anshuln/.local/lib/python3.6/site-packages/aiohttp/resolver.py", line 30, in resolve
    host, port, type=socket.SOCK_STREAM, family=family)
  File "/usr/lib/python3.6/concurrent/futures/thread.py", line 56, in run
    result = self.fn(*self.args, **self.kwargs)
  File "/usr/lib/python3.6/socket.py", line 745, in getaddrinfo
    for res in _socket.getaddrinfo(host, port, family, type, proto, flags):
socket.gaierror: [Errno -2] Name or service not known

The above exception was the direct cause of the following exception:

Traceback (most recent call last):
  File "/home/anshuln/.local/lib/python3.6/site-packages/discord/client.py", line 499, in connect
    await self._connect()
  File "/home/anshuln/.local/lib/python3.6/site-packages/discord/client.py", line 460, in _connect
    self.ws = await asyncio.wait_for(coro, timeout=180.0)
  File "/usr/lib/python3.6/asyncio/tasks.py", line 358, in wait_for
    return fut.result()
  File "/home/anshuln/.local/lib/python3.6/site-packages/discord/gateway.py", line 224, in from_client
    gateway = await client.http.get_gateway()
  File "/home/anshuln/.local/lib/python3.6/site-packages/discord/http.py", line 827, in get_gateway
    data = await self.request(Route('GET', '/gateway'))
  File "/home/anshuln/.local/lib/python3.6/site-packages/discord/http.py", line 165, in request
    async with self.__session.request(method, url, **kwargs) as r:
  File "/home/anshuln/.local/lib/python3.6/site-packages/aiohttp/client.py", line 1012, in __aenter__
    self._resp = await self._coro
  File "/home/anshuln/.local/lib/python3.6/site-packages/aiohttp/client.py", line 483, in _request
    timeout=real_timeout
  File "/home/anshuln/.local/lib/python3.6/site-packages/aiohttp/connector.py", line 523, in connect
    proto = await self._create_connection(req, traces, timeout)
  File "/home/anshuln/.local/lib/python3.6/site-packages/aiohttp/connector.py", line 859, in _create_connection
    req, traces, timeout)
  File "/home/anshuln/.local/lib/python3.6/site-packages/aiohttp/connector.py", line 971, in _create_direct_connection
    raise ClientConnectorError(req.connection_key, exc) from exc
aiohttp.client_exceptions.ClientConnectorError: Cannot connect to host discordapp.com:443 ssl:default [Name or service not known]
2020-03-26 19:49:38,533:ERROR:discord.client: Attempting a reconnect in 2.64s
Traceback (most recent call last):
  File "/home/anshuln/.local/lib/python3.6/site-packages/aiohttp/connector.py", line 967, in _create_direct_connection
    traces=traces), loop=self._loop)
  File "/home/anshuln/.local/lib/python3.6/site-packages/aiohttp/connector.py", line 830, in _resolve_host
    self._resolver.resolve(host, port, family=self._family)
  File "/home/anshuln/.local/lib/python3.6/site-packages/aiohttp/resolver.py", line 30, in resolve
    host, port, type=socket.SOCK_STREAM, family=family)
  File "/usr/lib/python3.6/concurrent/futures/thread.py", line 56, in run
    result = self.fn(*self.args, **self.kwargs)
  File "/usr/lib/python3.6/socket.py", line 745, in getaddrinfo
    for res in _socket.getaddrinfo(host, port, family, type, proto, flags):
socket.gaierror: [Errno -2] Name or service not known

The above exception was the direct cause of the following exception:

Traceback (most recent call last):
  File "/home/anshuln/.local/lib/python3.6/site-packages/discord/client.py", line 499, in connect
    await self._connect()
  File "/home/anshuln/.local/lib/python3.6/site-packages/discord/client.py", line 460, in _connect
    self.ws = await asyncio.wait_for(coro, timeout=180.0)
  File "/usr/lib/python3.6/asyncio/tasks.py", line 358, in wait_for
    return fut.result()
  File "/home/anshuln/.local/lib/python3.6/site-packages/discord/gateway.py", line 224, in from_client
    gateway = await client.http.get_gateway()
  File "/home/anshuln/.local/lib/python3.6/site-packages/discord/http.py", line 827, in get_gateway
    data = await self.request(Route('GET', '/gateway'))
  File "/home/anshuln/.local/lib/python3.6/site-packages/discord/http.py", line 165, in request
    async with self.__session.request(method, url, **kwargs) as r:
  File "/home/anshuln/.local/lib/python3.6/site-packages/aiohttp/client.py", line 1012, in __aenter__
    self._resp = await self._coro
  File "/home/anshuln/.local/lib/python3.6/site-packages/aiohttp/client.py", line 483, in _request
    timeout=real_timeout
  File "/home/anshuln/.local/lib/python3.6/site-packages/aiohttp/connector.py", line 523, in connect
    proto = await self._create_connection(req, traces, timeout)
  File "/home/anshuln/.local/lib/python3.6/site-packages/aiohttp/connector.py", line 859, in _create_connection
    req, traces, timeout)
  File "/home/anshuln/.local/lib/python3.6/site-packages/aiohttp/connector.py", line 971, in _create_direct_connection
    raise ClientConnectorError(req.connection_key, exc) from exc
aiohttp.client_exceptions.ClientConnectorError: Cannot connect to host discordapp.com:443 ssl:default [Name or service not known]
2020-03-26 19:49:45,487:ERROR:discord.client: Attempting a reconnect in 186.63s
Traceback (most recent call last):
  File "/home/anshuln/.local/lib/python3.6/site-packages/aiohttp/connector.py", line 967, in _create_direct_connection
    traces=traces), loop=self._loop)
  File "/home/anshuln/.local/lib/python3.6/site-packages/aiohttp/connector.py", line 830, in _resolve_host
    self._resolver.resolve(host, port, family=self._family)
  File "/home/anshuln/.local/lib/python3.6/site-packages/aiohttp/resolver.py", line 30, in resolve
    host, port, type=socket.SOCK_STREAM, family=family)
  File "/usr/lib/python3.6/concurrent/futures/thread.py", line 56, in run
    result = self.fn(*self.args, **self.kwargs)
  File "/usr/lib/python3.6/socket.py", line 745, in getaddrinfo
    for res in _socket.getaddrinfo(host, port, family, type, proto, flags):
socket.gaierror: [Errno -2] Name or service not known

The above exception was the direct cause of the following exception:

Traceback (most recent call last):
  File "/home/anshuln/.local/lib/python3.6/site-packages/discord/client.py", line 499, in connect
    await self._connect()
  File "/home/anshuln/.local/lib/python3.6/site-packages/discord/client.py", line 460, in _connect
    self.ws = await asyncio.wait_for(coro, timeout=180.0)
  File "/usr/lib/python3.6/asyncio/tasks.py", line 358, in wait_for
    return fut.result()
  File "/home/anshuln/.local/lib/python3.6/site-packages/discord/gateway.py", line 224, in from_client
    gateway = await client.http.get_gateway()
  File "/home/anshuln/.local/lib/python3.6/site-packages/discord/http.py", line 827, in get_gateway
    data = await self.request(Route('GET', '/gateway'))
  File "/home/anshuln/.local/lib/python3.6/site-packages/discord/http.py", line 165, in request
    async with self.__session.request(method, url, **kwargs) as r:
  File "/home/anshuln/.local/lib/python3.6/site-packages/aiohttp/client.py", line 1012, in __aenter__
    self._resp = await self._coro
  File "/home/anshuln/.local/lib/python3.6/site-packages/aiohttp/client.py", line 483, in _request
    timeout=real_timeout
  File "/home/anshuln/.local/lib/python3.6/site-packages/aiohttp/connector.py", line 523, in connect
    proto = await self._create_connection(req, traces, timeout)
  File "/home/anshuln/.local/lib/python3.6/site-packages/aiohttp/connector.py", line 859, in _create_connection
    req, traces, timeout)
  File "/home/anshuln/.local/lib/python3.6/site-packages/aiohttp/connector.py", line 971, in _create_direct_connection
    raise ClientConnectorError(req.connection_key, exc) from exc
aiohttp.client_exceptions.ClientConnectorError: Cannot connect to host discordapp.com:443 ssl:default [Name or service not known]
2020-03-26 20:57:03,539:INFO:discord.gateway: Created websocket connected to wss://gateway.discord.gg?encoding=json&v=6&compress=zlib-stream
2020-03-26 20:57:03,540:INFO:discord.gateway: Shard ID None has sent the IDENTIFY payload.
2020-03-26 20:57:03,978:INFO:discord.gateway: Shard ID None has connected to Gateway: ["gateway-prd-main-tc7w",{"micros":54463,"calls":["discord-sessions-prd-1-75",{"micros":46635,"calls":["start_session",{"micros":45173,"calls":["api-prd-main-2tsj",{"micros":42324,"calls":["get_user",{"micros":2971},"add_authorized_ip",{"micros":1729},"get_guilds",{"micros":11559},"coros_wait",{"micros":2}]}]},"guilds_connect",{"micros":2,"calls":[]},"presence_connect",{"micros":62,"calls":[]}]}]}] (Session ID: 95403a5c57da81da50e16018ad519f19).
2020-03-26 22:44:35,123:INFO:discord.gateway: Websocket closed with 1001 (), attempting a reconnect.
2020-03-26 22:44:35,147:INFO:discord.client: Got a request to RESUME the websocket.
2020-03-26 22:44:37,769:INFO:discord.gateway: Created websocket connected to wss://gateway.discord.gg?encoding=json&v=6&compress=zlib-stream
2020-03-26 22:44:37,772:INFO:discord.gateway: Shard ID None has sent the RESUME payload.
2020-03-26 22:44:38,177:INFO:discord.gateway: Shard ID None has successfully RESUMED session 95403a5c57da81da50e16018ad519f19 under trace ["gateway-prd-main-ghdc",{"micros":10938,"calls":["discord-sessions-prd-1-75",{"micros":14}]}].
2020-03-26 22:45:41,355:WARNING:discord.gateway: Shard ID None has stopped responding to the gateway. Closing and restarting.
2020-03-26 23:11:21,321:INFO:discord.gateway: Websocket closed with 1006 (), attempting a reconnect.
2020-03-26 23:11:21,321:INFO:discord.client: Got a request to RESUME the websocket.
2020-03-26 23:11:26,595:WARNING:discord.gateway: Shard ID None has stopped responding to the gateway. Closing and restarting.
2020-03-26 23:13:34,047:INFO:discord.gateway: Created websocket connected to wss://gateway.discord.gg?encoding=json&v=6&compress=zlib-stream
2020-03-26 23:13:34,063:INFO:discord.gateway: Shard ID None has sent the RESUME payload.
2020-03-26 23:13:34,444:INFO:discord.gateway: Shard ID None session has been invalidated.
2020-03-26 23:13:39,447:INFO:discord.gateway: Shard ID None has sent the IDENTIFY payload.
2020-03-26 23:13:39,867:INFO:discord.gateway: Shard ID None has connected to Gateway: ["gateway-prd-main-shrn",{"micros":85721,"calls":["discord-sessions-prd-1-50",{"micros":84139,"calls":["start_session",{"micros":81680,"calls":["api-prd-main-rvx7",{"micros":77909,"calls":["get_user",{"micros":4179},"add_authorized_ip",{"micros":6646},"get_guilds",{"micros":5054},"coros_wait",{"micros":2}]}]},"guilds_connect",{"micros":2,"calls":[]},"presence_connect",{"micros":816,"calls":[]}]}]}] (Session ID: 2a861bc564d31066ed0e6ab4d4209602).
2020-03-27 00:11:24,222:WARNING:discord.gateway: Heartbeat blocked for more than 5 seconds.
2020-03-27 11:31:05,978:WARNING:discord.gateway: Heartbeat blocked for more than 10 seconds.
2020-03-27 11:31:10,979:WARNING:discord.gateway: Heartbeat blocked for more than 15 seconds.
2020-03-27 11:31:15,980:WARNING:discord.gateway: Heartbeat blocked for more than 20 seconds.
2020-03-27 11:31:17,523:INFO:discord.gateway: Websocket closed with 1006 (), attempting a reconnect.
2020-03-27 11:31:17,523:INFO:discord.client: Got a request to RESUME the websocket.
2020-03-27 11:31:19,357:INFO:discord.gateway: Created websocket connected to wss://gateway.discord.gg?encoding=json&v=6&compress=zlib-stream
2020-03-27 11:31:19,359:INFO:discord.gateway: Shard ID None has sent the RESUME payload.
2020-03-27 11:31:19,662:INFO:discord.gateway: Shard ID None session has been invalidated.
2020-03-27 11:31:24,665:INFO:discord.gateway: Shard ID None has sent the IDENTIFY payload.
2020-03-27 11:31:25,046:INFO:discord.gateway: Shard ID None has connected to Gateway: ["gateway-prd-main-4fdw",{"micros":83213,"calls":["discord-sessions-prd-1-35",{"micros":73603,"calls":["start_session",{"micros":67295,"calls":["api-prd-main-zpr3",{"micros":64162,"calls":["get_user",{"micros":7381},"add_authorized_ip",{"micros":3374},"get_guilds",{"micros":6096},"coros_wait",{"micros":2}]}]},"guilds_connect",{"micros":2,"calls":[]},"presence_connect",{"micros":3740,"calls":[]}]}]}] (Session ID: 9c17303db5ee3a4bb3b0fb099e57bd7f).
2020-03-27 11:31:58,775:WARNING:discord.gateway: Shard ID None has stopped responding to the gateway. Closing and restarting.
2020-03-27 11:32:16,508:WARNING:discord.gateway: Can't keep up, websocket is 15.9s behind.
                                                                                                                                                                                           